
Validation sanity check:   0%|                                                                                                                            | 0/2 [00:00<?, ?it/s]
  | Name    | Type             | Params
---------------------------------------------
0 | model   | customMLP        | 104 K
1 | loss_fn | CrossEntropyLoss | 0
---------------------------------------------
104 K     Trainable params
0         Non-trainable params
104 K     Total params
0.418     Total estimated model params size (MB)
/home/daniel/miniconda3/lib/python3.9/site-packages/pytorch_lightning/trainer/data_loading.py:633: UserWarning: Your `val_dataloader` has `shuffle=True`, it is strongly recommended that you turn this off for val/test/predict dataloaders.
  rank_zero_warn(
Traceback (most recent call last):
  File "/home/daniel/FYT/comp4332/comp4332_project1/main.py", line 65, in <module>
    main(args)
  File "/home/daniel/FYT/comp4332/comp4332_project1/main.py", line 50, in main
    trainer.fit(model, dm)
  File "/home/daniel/miniconda3/lib/python3.9/site-packages/pytorch_lightning/trainer/trainer.py", line 737, in fit
    self._call_and_handle_interrupt(
  File "/home/daniel/miniconda3/lib/python3.9/site-packages/pytorch_lightning/trainer/trainer.py", line 682, in _call_and_handle_interrupt
    return trainer_fn(*args, **kwargs)
  File "/home/daniel/miniconda3/lib/python3.9/site-packages/pytorch_lightning/trainer/trainer.py", line 772, in _fit_impl
    self._run(model, ckpt_path=ckpt_path)
  File "/home/daniel/miniconda3/lib/python3.9/site-packages/pytorch_lightning/trainer/trainer.py", line 1194, in _run
    self._dispatch()
  File "/home/daniel/miniconda3/lib/python3.9/site-packages/pytorch_lightning/trainer/trainer.py", line 1274, in _dispatch
    self.training_type_plugin.start_training(self)
  File "/home/daniel/miniconda3/lib/python3.9/site-packages/pytorch_lightning/plugins/training_type/training_type_plugin.py", line 202, in start_training
    self._results = trainer.run_stage()
  File "/home/daniel/miniconda3/lib/python3.9/site-packages/pytorch_lightning/trainer/trainer.py", line 1284, in run_stage
    return self._run_train()
  File "/home/daniel/miniconda3/lib/python3.9/site-packages/pytorch_lightning/trainer/trainer.py", line 1306, in _run_train
    self._run_sanity_check(self.lightning_module)
  File "/home/daniel/miniconda3/lib/python3.9/site-packages/pytorch_lightning/trainer/trainer.py", line 1370, in _run_sanity_check
    self._evaluation_loop.run()
  File "/home/daniel/miniconda3/lib/python3.9/site-packages/pytorch_lightning/loops/base.py", line 145, in run
    self.advance(*args, **kwargs)
  File "/home/daniel/miniconda3/lib/python3.9/site-packages/pytorch_lightning/loops/dataloader/evaluation_loop.py", line 110, in advance
    dl_outputs = self.epoch_loop.run(dataloader, dataloader_idx, dl_max_batches, self.num_dataloaders)
  File "/home/daniel/miniconda3/lib/python3.9/site-packages/pytorch_lightning/loops/base.py", line 140, in run
    self.on_run_start(*args, **kwargs)
  File "/home/daniel/miniconda3/lib/python3.9/site-packages/pytorch_lightning/loops/epoch/evaluation_epoch_loop.py", line 86, in on_run_start
    self._dataloader_iter = _update_dataloader_iter(data_fetcher, self.batch_progress.current.ready)
  File "/home/daniel/miniconda3/lib/python3.9/site-packages/pytorch_lightning/loops/utilities.py", line 121, in _update_dataloader_iter
    dataloader_iter = enumerate(data_fetcher, batch_idx)
  File "/home/daniel/miniconda3/lib/python3.9/site-packages/pytorch_lightning/utilities/fetching.py", line 199, in __iter__
    self.prefetching(self.prefetch_batches)
  File "/home/daniel/miniconda3/lib/python3.9/site-packages/pytorch_lightning/utilities/fetching.py", line 258, in prefetching
    self._fetch_next_batch()
  File "/home/daniel/miniconda3/lib/python3.9/site-packages/pytorch_lightning/utilities/fetching.py", line 300, in _fetch_next_batch
    batch = next(self.dataloader_iter)
  File "/home/daniel/.local/lib/python3.9/site-packages/torch/utils/data/dataloader.py", line 652, in __next__
    data = self._next_data()
  File "/home/daniel/.local/lib/python3.9/site-packages/torch/utils/data/dataloader.py", line 1347, in _next_data
    return self._process_data(data)
  File "/home/daniel/.local/lib/python3.9/site-packages/torch/utils/data/dataloader.py", line 1373, in _process_data
    data.reraise()
  File "/home/daniel/.local/lib/python3.9/site-packages/torch/_utils.py", line 461, in reraise
    raise exception
NameError: Caught NameError in DataLoader worker process 0.
Original Traceback (most recent call last):
  File "/home/daniel/.local/lib/python3.9/site-packages/torch/utils/data/_utils/worker.py", line 302, in _worker_loop
    data = fetcher.fetch(index)
  File "/home/daniel/.local/lib/python3.9/site-packages/torch/utils/data/_utils/fetch.py", line 49, in fetch
    data = [self.dataset[idx] for idx in possibly_batched_index]
  File "/home/daniel/.local/lib/python3.9/site-packages/torch/utils/data/_utils/fetch.py", line 49, in <listcomp>
    data = [self.dataset[idx] for idx in possibly_batched_index]
  File "/home/daniel/FYT/comp4332/comp4332_project1/data/data.py", line 31, in __getitem__
    return torch.from_numpy(x), y
NameError: name 'torch' is not defined